<!-- ./model/hero/boat.xml -->
<mujoco>
    <option gravity="0 0 -9.81" integrator="RK4" timestep="0.01"/>
    <asset>
        <texture name="grid" type="2d" builtin="checker" width="512" height="512" rgb1="0.2 0.2 0.2" rgb2="0.3 0.3 0.3"/>
        <material name="grid" texture="grid" texrepeat="10 10" texuniform="true" reflectance=".3"/>
    </asset>

    <default>
        <joint damping="0.03"/>
        <geom density="500" friction="0.8 0.8 0.8"/>
    </default>

    <worldbody>
        <geom name="grid" type="plane" size="0 0 .01" material="grid"/>

        <!-- Boat -->
        <body name="boat" pos="0 0 0.5">
            <freejoint />
            <!-- Hull -->
            <light name="boat_light" pos="0 0 2" mode="trackcom" diffuse="0.7 0.7 0.7"/>
            <geom type="box" size="0.5 0.3 0.2" rgba="1 1 0 1" />
             <!-- Left and Right thruster -->
            <body name="thruster left" pos="-0.5 0.4 0" euler="0 90 0">
                <joint name="propeller_left_joint" type="hinge" axis="0 0 1" />
                <geom type="cylinder" size="0.05 0.05" rgba="0 0 0 1"/>
                <geom type="box" size="0.02 0.15 0.01" pos="0 0 -0.05" rgba="0 1 0 1"/>
            </body>
            <body name="thruster right" pos="-0.5 -0.4 0" euler="0 90 0">
                <joint name="propeller_right_joint" type="hinge" axis="0 0 1" />
                <geom type="cylinder" size="0.05 0.05" rgba="0 0 0 1"/>
                <geom type="box" size="0.02 0.15 0.01" pos="0 0 -0.05" rgba="0 1 0 1"/>
            </body>
        </body>
    </worldbody>

    <actuator>
        <!-- Left and Right thruster -->
        <motor name="left_motor" joint="propeller_left_joint" ctrlrange="-5 5"/>
        <motor name="right_motor" joint="propeller_right_joint" ctrlrange="-5 5"/>
    </actuator>
</mujoco>
